2023-05-26 15:51:09 (connectionpool.py:1048) DEBUG    Starting new HTTPS connection (1): www.baidu.com:443
2023-05-26 15:51:09 (connectionpool.py:546) DEBUG    https://www.baidu.com:443 "GET / HTTP/1.1" 200 None
2023-05-26 15:51:09 (test_casedome.py:26 ) ERROR    main Exception: Traceback (most recent call last):
  File "C:\Users\Hasee\PycharmProjects\pythonProjectForWork\interfaceAutomationTest\case\test_casedome.py", line 23, in test_01
    assert result == resp.status_code()
TypeError: 'int' object is not callable